<?xml version="1.0"?>
<robot name="humanoid_robot">
  <!-- Torso -->
  <link name="torso">
    <visual>
      <geometry>
        <box size="0.3 0.2 0.5"/>
      </geometry>
      <material name="blue">
        <color rgba="0.0 0.0 1.0 1.0"/>
      </material>
    </visual>
    <collision>
      <geometry>
        <box size="0.3 0.2 0.5"/>
      </geometry>
    </collision>
    <inertial>
      <mass value="10.0"/>
      <origin xyz="0 0 0" rpy="0 0 0"/>
      <inertia ixx="0.1" ixy="0.0" ixz="0.0" iyy="0.1" iyz="0.0" izz="0.1"/>
    </inertial>
  </link>

  <!-- Head -->
  <link name="head">
    <visual>
      <geometry>
        <sphere radius="0.1"/>
      </geometry>
      <material name="skin">
        <color rgba="1.0 0.8 0.6 1.0"/>
      </material>
    </visual>
    <collision>
      <geometry>
        <sphere radius="0.1"/>
      </geometry>
    </collision>
    <inertial>
      <mass value="2.0"/>
      <origin xyz="0 0 0.25" rpy="0 0 0"/>
      <inertia ixx="0.02" ixy="0.0" ixz="0.0" iyy="0.02" iyz="0.0" izz="0.02"/>
    </inertial>
  </link>
  <joint name="neck_joint" type="fixed">
    <parent link="torso"/>
    <child link="head"/>
    <origin xyz="0 0 0.35" rpy="0 0 0"/>
  </joint>

  <!-- Left Arm -->
  <link name="left_arm">
    <visual>
      <geometry>
        <cylinder radius="0.05" length="0.4"/>
      </geometry>
      <material name="grey">
        <color rgba="0.5 0.5 0.5 1.0"/>
      </material>
    </visual>
    <collision>
      <geometry>
        <cylinder radius="0.05" length="0.4"/>
      </geometry>
    </collision>
    <inertial>
      <mass value="3.0"/>
      <origin xyz="0 0 0" rpy="0 0 0"/>
      <inertia ixx="0.03" ixy="0.0" ixz="0.0" iyy="0.03" iyz="0.0" izz="0.03"/>
    </inertial>
  </link>
  <joint name="left_shoulder_joint" type="revolute">
    <parent link="torso"/>
    <child link="left_arm"/>
    <origin xyz="0.15 0.1 0.2" rpy="0 0 0"/>
    <axis xyz="0 1 0"/>
    <limit lower="-1.57" upper="1.57" effort="10" velocity="1.0"/>
  </joint>

  <!-- Right Arm -->
  <link name="right_arm">
    <visual>
      <geometry>
        <cylinder radius="0.05" length="0.4"/>
      </geometry>
      <material name="grey">
        <color rgba="0.5 0.5 0.5 1.0"/>
      </material>
    </visual>
    <collision>
      <geometry>
        <cylinder radius="0.05" length="0.4"/>
      </geometry>
    </collision>
    <inertial>
      <mass value="3.0"/>
      <origin xyz="0 0 0" rpy="0 0 0"/>
      <inertia ixx="0.03" ixy="0.0" ixz="0.0" iyy="0.03" iyz="0.0" izz="0.03"/>
    </inertial>
  </link>
  <joint name="right_shoulder_joint" type="revolute">
    <parent link="torso"/>
    <child link="right_arm"/>
    <origin xyz="-0.15 0.1 0.2" rpy="0 0 0"/>
    <axis xyz="0 1 0"/>
    <limit lower="-1.57" upper="1.57" effort="10" velocity="1.0"/>
  </joint>

  <!-- Left Leg -->
  <link name="left_leg">
    <visual>
      <geometry>
        <cylinder radius="0.05" length="0.4"/>
      </geometry>
      <material name="grey">
        <color rgba="0.5 0.5 0.5 1.0"/>
      </material>
    </visual>
    <collision>
      <geometry>
        <cylinder radius="0.05" length="0.4"/>
      </geometry>
    </collision>
    <inertial>
      <mass value="5.0"/>
      <origin xyz="0 0 0" rpy="0 0 0"/>
      <inertia ixx="0.05" ixy="0.0" ixz="0.0" iyy="0.05" iyz="0.0" izz="0.05"/>
    </inertial>
  </link>
  <joint name="left_hip_joint" type="revolute">
    <parent link="torso"/>
    <child link="left_leg"/>
    <origin xyz="0.1 0 -0.25" rpy="0 0 0"/>
    <axis xyz="1 0 0"/>
    <limit lower="-1.57" upper="1.57" effort="10" velocity="1.0"/>
  </joint>

  <!-- Right Leg -->
  <link name="right_leg">
    <visual>
      <geometry>
        <cylinder radius="0.05" length="0.4"/>
      </geometry>
      <material name="grey">
        <color rgba="0.5 0.5 0.5 1.0"/>
      </material>
    </visual>
    <collision>
      <geometry>
        <cylinder radius="0.05" length="0.4"/>
      </geometry>
    </collision>
    <inertial>
      <mass value="5.0"/>
      <origin xyz="0 0 0" rpy="0 0 0"/>
      <inertia ixx="0.05" ixy="0.0" ixz="0.0" iyy="0.05" iyz="0.0" izz="0.05"/>
    </inertial>
  </link>
  <joint name="right_hip_joint" type="revolute">
    <parent link="torso"/>
    <child link="right_leg"/>
    <origin xyz="-0.1 0 -0.25" rpy="0 0 0"/>
    <axis xyz="1 0 0"/>
    <limit lower="-1.57" upper="1.57" effort="10" velocity="1.0"/>
  </joint>
</robot>