<robot name="">
	<link name="torso">
		<inertial>
			<origin rpy="0.00000 -0.00000 0.00000" xyz="-0.00500 0.00000 -0.06000" />
			<mass value="1.11343" />
			<inertia ixx="0.00673" ixy="0.00000" ixz="0.00000" iyy="0.00566" iyz="0.00000" izz="0.00257" />
		</inertial>
		<collision>
			<origin rpy="-1.57080 0.00000 0.00000" xyz="0.00000 0.00000 0.00000" />
			<geometry>
				<capsule length="0.07000" radius="0.03500" />
			</geometry>
		</collision>
		<collision>
			<origin rpy="0.00000 -0.00000 0.00000" xyz="0.00000 0.00000 0.09500" />
			<geometry>
				<sphere radius="0.04500" />
			</geometry>
		</collision>
		<collision>
			<origin rpy="-1.57080 0.00000 0.00000" xyz="-0.00500 0.00000 -0.06000" />
			<geometry>
				<capsule length="0.06000" radius="0.03000" />
			</geometry>
		</collision>
	</link>
	<link name="link1_2">
		<inertial>
			<origin rpy="0.00000 -0.00000 0.00000" xyz="0.00000 0.00000 0.00000" />
			<mass value="0.00000" />
			<inertia ixx="0.00000" ixy="0.00000" ixz="0.00000" iyy="0.00000" iyz="0.00000" izz="0.00000" />
		</inertial>
	</link>
	<link name="link1_3">
		<inertial>
			<origin rpy="0.00000 -0.00000 0.00000" xyz="0.00000 0.00000 0.00000" />
			<mass value="0.00000" />
			<inertia ixx="0.00000" ixy="0.00000" ixz="0.00000" iyy="0.00000" iyz="0.00000" izz="0.00000" />
		</inertial>
	</link>
	<link name="lwaist">
		<inertial>
			<origin rpy="0.00000 -0.00000 0.00000" xyz="0.00000 0.00000 0.00000" />
			<mass value="0.28274" />
			<inertia ixx="0.00042" ixy="0.00000" ixz="0.00000" iyy="0.00017" iyz="0.00000" izz="0.00042" />
		</inertial>
		<collision>
			<origin rpy="-1.57080 0.00000 0.00000" xyz="0.00000 0.00000 0.00000" />
			<geometry>
				<capsule length="0.06000" radius="0.03000" />
			</geometry>
		</collision>
	</link>
	<link name="link1_5">
		<inertial>
			<origin rpy="0.00000 -0.00000 0.00000" xyz="0.00000 0.00000 0.00000" />
			<mass value="0.00000" />
			<inertia ixx="0.00000" ixy="0.00000" ixz="0.00000" iyy="0.00000" iyz="0.00000" izz="0.00000" />
		</inertial>
	</link>
	<link name="pelvis">
		<inertial>
			<origin rpy="0.00000 -0.00000 0.00000" xyz="-0.01000 0.00000 0.00000" />
			<mass value="0.82702" />
			<inertia ixx="0.00232" ixy="0.00000" ixz="0.00000" iyy="0.00112" iyz="0.00000" izz="0.00232" />
		</inertial>
		<collision>
			<origin rpy="-1.57080 0.00000 0.00000" xyz="-0.01000 0.00000 0.00000" />
			<geometry>
				<capsule length="0.07000" radius="0.04500" />
			</geometry>
		</collision>
	</link>
	<link name="link1_7">
		<inertial>
			<origin rpy="0.00000 -0.00000 0.00000" xyz="0.00000 0.00000 0.00000" />
			<mass value="0.00000" />
			<inertia ixx="0.00000" ixy="0.00000" ixz="0.00000" iyy="0.00000" iyz="0.00000" izz="0.00000" />
		</inertial>
	</link>
	<link name="link1_8">
		<inertial>
			<origin rpy="0.00000 -0.00000 0.00000" xyz="0.00000 0.00000 0.00000" />
			<mass value="0.00000" />
			<inertia ixx="0.00000" ixy="0.00000" ixz="0.00000" iyy="0.00000" iyz="0.00000" izz="0.00000" />
		</inertial>
	</link>
	<link name="link1_9">
		<inertial>
			<origin rpy="0.00000 -0.00000 0.00000" xyz="0.00000 0.00000 0.00000" />
			<mass value="0.00000" />
			<inertia ixx="0.00000" ixy="0.00000" ixz="0.00000" iyy="0.00000" iyz="0.00000" izz="0.00000" />
		</inertial>
	</link>
	<link name="right_thigh">
		<inertial>
			<origin rpy="0.00000 -0.00000 0.00000" xyz="0.00000 0.00250 -0.08500" />
			<mass value="0.59397" />
			<inertia ixx="0.00288" ixy="0.00000" ixz="0.00000" iyy="0.00284" iyz="0.00000" izz="0.00040" />
		</inertial>
		<collision>
			<origin rpy="-3.11219 -0.00000 0.00000" xyz="0.00000 0.00250 -0.08500" />
			<geometry>
				<capsule length="0.17008" radius="0.03000" />
			</geometry>
		</collision>
	</link>
	<link name="link1_11">
		<inertial>
			<origin rpy="0.00000 -0.00000 0.00000" xyz="0.00000 0.00000 0.00000" />
			<mass value="0.00000" />
			<inertia ixx="0.00000" ixy="0.00000" ixz="0.00000" iyy="0.00000" iyz="0.00000" izz="0.00000" />
		</inertial>
	</link>
	<link name="right_shin">
		<inertial>
			<origin rpy="0.00000 -0.00000 0.00000" xyz="0.00000 0.00000 -0.07500" />
			<mass value="0.34446" />
			<inertia ixx="0.00121" ixy="0.00000" ixz="0.00000" iyy="0.00121" iyz="0.00000" izz="0.00014" />
		</inertial>
		<collision>
			<origin rpy="3.14159 -0.00000 3.14159" xyz="0.00000 0.00000 -0.07500" />
			<geometry>
				<capsule length="0.15000" radius="0.02450" />
			</geometry>
		</collision>
	</link>
	<link name="link1_13">
		<inertial>
			<origin rpy="0.00000 -0.00000 0.00000" xyz="0.00000 0.00000 0.00000" />
			<mass value="0.00000" />
			<inertia ixx="0.00000" ixy="0.00000" ixz="0.00000" iyy="0.00000" iyz="0.00000" izz="0.00000" />
		</inertial>
	</link>
	<link name="link1_14">
		<inertial>
			<origin rpy="0.00000 -0.00000 0.00000" xyz="0.00000 0.00000 0.00000" />
			<mass value="0.00000" />
			<inertia ixx="0.00000" ixy="0.00000" ixz="0.00000" iyy="0.00000" iyz="0.00000" izz="0.00000" />
		</inertial>
	</link>
	<link name="right_foot">
		<inertial>
			<origin rpy="0.00000 -0.00000 0.00000" xyz="0.01750 0.00500 0.00000" />
			<mass value="0.14139" />
			<inertia ixx="0.00006" ixy="0.00000" ixz="0.00000" iyy="0.00022" iyz="0.00000" izz="0.00026" />
		</inertial>
		<collision>
			<origin rpy="1.57080 1.47585 1.47585" xyz="0.01750 -0.01500 0.00000" />
			<geometry>
				<capsule length="0.10547" radius="0.01350" />
			</geometry>
		</collision>
		<collision>
			<origin rpy="-1.57080 1.47585 -1.47585" xyz="0.01750 0.00500 0.00000" />
			<geometry>
				<capsule length="0.10547" radius="0.01350" />
			</geometry>
		</collision>
	</link>
	<link name="link1_16">
		<inertial>
			<origin rpy="0.00000 -0.00000 0.00000" xyz="0.00000 0.00000 0.00000" />
			<mass value="0.00000" />
			<inertia ixx="0.00000" ixy="0.00000" ixz="0.00000" iyy="0.00000" iyz="0.00000" izz="0.00000" />
		</inertial>
	</link>
	<link name="link1_17">
		<inertial>
			<origin rpy="0.00000 -0.00000 0.00000" xyz="0.00000 0.00000 0.00000" />
			<mass value="0.00000" />
			<inertia ixx="0.00000" ixy="0.00000" ixz="0.00000" iyy="0.00000" iyz="0.00000" izz="0.00000" />
		</inertial>
	</link>
	<link name="link1_18">
		<inertial>
			<origin rpy="0.00000 -0.00000 0.00000" xyz="0.00000 0.00000 0.00000" />
			<mass value="0.00000" />
			<inertia ixx="0.00000" ixy="0.00000" ixz="0.00000" iyy="0.00000" iyz="0.00000" izz="0.00000" />
		</inertial>
	</link>
	<link name="left_thigh">
		<inertial>
			<origin rpy="0.00000 -0.00000 0.00000" xyz="0.00000 -0.00250 -0.08500" />
			<mass value="0.59397" />
			<inertia ixx="0.00288" ixy="0.00000" ixz="0.00000" iyy="0.00284" iyz="0.00000" izz="0.00040" />
		</inertial>
		<collision>
			<origin rpy="3.11219 -0.00000 0.00000" xyz="0.00000 -0.00250 -0.08500" />
			<geometry>
				<capsule length="0.17008" radius="0.03000" />
			</geometry>
		</collision>
	</link>
	<link name="link1_20">
		<inertial>
			<origin rpy="0.00000 -0.00000 0.00000" xyz="0.00000 0.00000 0.00000" />
			<mass value="0.00000" />
			<inertia ixx="0.00000" ixy="0.00000" ixz="0.00000" iyy="0.00000" iyz="0.00000" izz="0.00000" />
		</inertial>
	</link>
	<link name="left_shin">
		<inertial>
			<origin rpy="0.00000 -0.00000 0.00000" xyz="0.00000 0.00000 -0.07500" />
			<mass value="0.34446" />
			<inertia ixx="0.00121" ixy="0.00000" ixz="0.00000" iyy="0.00121" iyz="0.00000" izz="0.00014" />
		</inertial>
		<collision>
			<origin rpy="3.14159 -0.00000 3.14159" xyz="0.00000 0.00000 -0.07500" />
			<geometry>
				<capsule length="0.15000" radius="0.02450" />
			</geometry>
		</collision>
	</link>
	<link name="link1_22">
		<inertial>
			<origin rpy="0.00000 -0.00000 0.00000" xyz="0.00000 0.00000 0.00000" />
			<mass value="0.00000" />
			<inertia ixx="0.00000" ixy="0.00000" ixz="0.00000" iyy="0.00000" iyz="0.00000" izz="0.00000" />
		</inertial>
	</link>
	<link name="link1_23">
		<inertial>
			<origin rpy="0.00000 -0.00000 0.00000" xyz="0.00000 0.00000 0.00000" />
			<mass value="0.00000" />
			<inertia ixx="0.00000" ixy="0.00000" ixz="0.00000" iyy="0.00000" iyz="0.00000" izz="0.00000" />
		</inertial>
	</link>
	<link name="left_foot">
		<inertial>
			<origin rpy="0.00000 -0.00000 0.00000" xyz="0.01750 -0.00500 0.00000" />
			<mass value="0.14139" />
			<inertia ixx="0.00006" ixy="0.00000" ixz="0.00000" iyy="0.00022" iyz="0.00000" izz="0.00026" />
		</inertial>
		<collision>
			<origin rpy="-1.57080 1.47585 -1.47585" xyz="0.01750 0.01500 0.00000" />
			<geometry>
				<capsule length="0.10547" radius="0.01350" />
			</geometry>
		</collision>
		<collision>
			<origin rpy="1.57080 1.47585 1.47585" xyz="0.01750 -0.00500 0.00000" />
			<geometry>
				<capsule length="0.10547" radius="0.01350" />
			</geometry>
		</collision>
	</link>
	<link name="link1_25">
		<inertial>
			<origin rpy="0.00000 -0.00000 0.00000" xyz="0.00000 0.00000 0.00000" />
			<mass value="0.00000" />
			<inertia ixx="0.00000" ixy="0.00000" ixz="0.00000" iyy="0.00000" iyz="0.00000" izz="0.00000" />
		</inertial>
	</link>
	<link name="link1_26">
		<inertial>
			<origin rpy="0.00000 -0.00000 0.00000" xyz="0.00000 0.00000 0.00000" />
			<mass value="0.00000" />
			<inertia ixx="0.00000" ixy="0.00000" ixz="0.00000" iyy="0.00000" iyz="0.00000" izz="0.00000" />
		</inertial>
	</link>
	<link name="right_upper_arm">
		<inertial>
			<origin rpy="0.00000 -0.00000 0.00000" xyz="0.04000 -0.04000 -0.04000" />
			<mass value="0.20763" />
			<inertia ixx="0.00074" ixy="0.00000" ixz="0.00000" iyy="0.00074" iyz="0.00000" izz="0.00071" />
		</inertial>
		<collision>
			<origin rpy="2.35619 0.61548 1.30900" xyz="0.04000 -0.04000 -0.04000" />
			<geometry>
				<capsule length="0.13856" radius="0.02000" />
			</geometry>
		</collision>
	</link>
	<link name="link1_28">
		<inertial>
			<origin rpy="0.00000 -0.00000 0.00000" xyz="0.00000 0.00000 0.00000" />
			<mass value="0.00000" />
			<inertia ixx="0.00000" ixy="0.00000" ixz="0.00000" iyy="0.00000" iyz="0.00000" izz="0.00000" />
		</inertial>
	</link>
	<link name="right_lower_arm">
		<inertial>
			<origin rpy="0.00000 -0.00000 0.00000" xyz="0.00000 0.00000 0.00000" />
			<mass value="0.15369" />
			<inertia ixx="0.00044" ixy="0.00000" ixz="0.00000" iyy="0.00044" iyz="0.00000" izz="0.00043" />
		</inertial>
		<collision>
			<origin rpy="-0.78540 0.61548 -0.26180" xyz="0.04500 0.04500 0.04500" />
			<geometry>
				<capsule length="0.13856" radius="0.01550" />
			</geometry>
		</collision>
		<collision>
			<origin rpy="0.00000 -0.00000 0.00000" xyz="0.09000 0.09000 0.09000" />
			<geometry>
				<sphere radius="0.02000" />
			</geometry>
		</collision>
	</link>
	<link name="link1_30">
		<inertial>
			<origin rpy="0.00000 -0.00000 0.00000" xyz="0.00000 0.00000 0.00000" />
			<mass value="0.00000" />
			<inertia ixx="0.00000" ixy="0.00000" ixz="0.00000" iyy="0.00000" iyz="0.00000" izz="0.00000" />
		</inertial>
	</link>
	<link name="link1_31">
		<inertial>
			<origin rpy="0.00000 -0.00000 0.00000" xyz="0.00000 0.00000 0.00000" />
			<mass value="0.00000" />
			<inertia ixx="0.00000" ixy="0.00000" ixz="0.00000" iyy="0.00000" iyz="0.00000" izz="0.00000" />
		</inertial>
	</link>
	<link name="left_upper_arm">
		<inertial>
			<origin rpy="0.00000 -0.00000 0.00000" xyz="0.04000 0.04000 -0.04000" />
			<mass value="0.20763" />
			<inertia ixx="0.00074" ixy="0.00000" ixz="0.00000" iyy="0.00074" iyz="0.00000" izz="0.00071" />
		</inertial>
		<collision>
			<origin rpy="-2.35619 0.61548 -1.30900" xyz="0.04000 0.04000 -0.04000" />
			<geometry>
				<capsule length="0.13856" radius="0.02000" />
			</geometry>
		</collision>
	</link>
	<link name="link1_33">
		<inertial>
			<origin rpy="0.00000 -0.00000 0.00000" xyz="0.00000 0.00000 0.00000" />
			<mass value="0.00000" />
			<inertia ixx="0.00000" ixy="0.00000" ixz="0.00000" iyy="0.00000" iyz="0.00000" izz="0.00000" />
		</inertial>
	</link>
	<link name="left_lower_arm">
		<inertial>
			<origin rpy="0.00000 -0.00000 0.00000" xyz="0.00000 0.00000 0.00000" />
			<mass value="0.15369" />
			<inertia ixx="0.00044" ixy="0.00000" ixz="0.00000" iyy="0.00044" iyz="0.00000" izz="0.00043" />
		</inertial>
		<collision>
			<origin rpy="0.78540 0.61548 0.26180" xyz="0.04500 -0.04500 0.04500" />
			<geometry>
				<capsule length="0.13856" radius="0.01550" />
			</geometry>
		</collision>
		<collision>
			<origin rpy="0.00000 -0.00000 0.00000" xyz="0.09000 -0.09000 0.09000" />
			<geometry>
				<sphere radius="0.02000" />
			</geometry>
		</collision>
	</link>
	<joint name="abdomen_z" type="continuous">
		<parent link="torso" />
		<child link="link1_2" />
		<dynamics damping="1.0" friction="0.0001" />
		<origin rpy="0.00000 -0.00400 0.00000" xyz="-0.00513 0.00000 -0.09750" />
		<axis xyz="0.00000 0.00000 1.00000" />
	</joint>
	<joint name="abdomen_y" type="continuous">
		<parent link="link1_2" />
		<child link="link1_3" />
		<dynamics damping="1.0" friction="0.0001" />
		<origin rpy="0.00000 -0.00000 0.00000" xyz="0.00000 0.00000 0.00000" />
		<axis xyz="0.00000 1.00000 0.00000" />
	</joint>
	<joint name="jointfix_7_3" type="fixed">
		<parent link="link1_3" />
		<child link="lwaist" />
		<dynamics damping="1.0" friction="0.0001" />
		<origin rpy="0.00000 -0.00000 0.00000" xyz="0.00000 0.00000 -0.03250" />
		<axis xyz="0.00000 0.00000 0.00000" />
	</joint>
	<joint name="abdomen_x" type="continuous">
		<parent link="lwaist" />
		<child link="link1_5" />
		<dynamics damping="1.0" friction="0.0001" />
		<origin rpy="0.00000 -0.00400 0.00000" xyz="-0.00020 0.00000 -0.03250" />
		<axis xyz="1.00000 0.00000 0.00000" />
	</joint>
	<joint name="jointfix_6_5" type="fixed">
		<parent link="link1_5" />
		<child link="pelvis" />
		<dynamics damping="1.0" friction="0.0001" />
		<origin rpy="0.00000 -0.00000 0.00000" xyz="0.00000 0.00000 -0.05000" />
		<axis xyz="0.00000 0.00000 0.00000" />
	</joint>
	<joint name="right_hip_x" type="continuous">
		<parent link="pelvis" />
		<child link="link1_7" />
		<dynamics damping="1.0" friction="0.0001" />
		<origin rpy="0.00000 -0.00000 0.00000" xyz="0.00000 -0.05000 -0.02000" />
		<axis xyz="1.00000 0.00000 0.00000" />
	</joint>
	<joint name="right_hip_z" type="continuous">
		<parent link="link1_7" />
		<child link="link1_8" />
		<dynamics damping="1.0" friction="0.0001" />
		<origin rpy="0.00000 -0.00000 0.00000" xyz="0.00000 0.00000 0.00000" />
		<axis xyz="0.00000 0.00000 1.00000" />
	</joint>
	<joint name="right_hip_y" type="continuous">
		<parent link="link1_8" />
		<child link="link1_9" />
		<dynamics damping="1.0" friction="0.0001" />
		<origin rpy="0.00000 -0.00000 0.00000" xyz="0.00000 0.00000 0.00000" />
		<axis xyz="0.00000 1.00000 0.00000" />
	</joint>
	<joint name="jointfix_2_9" type="fixed">
		<parent link="link1_9" />
		<child link="right_thigh" />
		<dynamics damping="1.0" friction="0.0001" />
		<origin rpy="0.00000 -0.00000 0.00000" xyz="0.00000 0.00000 0.00000" />
		<axis xyz="0.00000 0.00000 0.00000" />
	</joint>
	<joint name="right_knee" type="continuous">
		<parent link="right_thigh" />
		<child link="link1_11" />
		<dynamics damping="1.0" friction="0.0001" />
		<origin rpy="0.00000 0.00000 0.00000" xyz="0.00000 0.00000 -0.19150" />
		<axis xyz="0.00000 -1.00000 0.00000" />
  </joint>
	<joint name="jointfix_1_11" type="fixed">
		<parent link="link1_11" />
		<child link="right_shin" />
		<dynamics damping="1.0" friction="0.0001" />
		<origin rpy="0.00000 -0.00000 0.00000" xyz="0.00000 0.00000 -0.01000" />
		<axis xyz="0.00000 0.00000 0.00000" />
	</joint>
	<joint name="right_ankle_y" type="continuous">
		<parent link="right_shin" />
		<child link="link1_13" />
		<dynamics damping="1.0" friction="0.0001" />
		<origin rpy="0.00000 0.00000 0.00000" xyz="0.00000 0.00000 -0.15500" />
		<axis xyz="0.00000 1.00000 0.00000" />
	</joint>
	<joint name="right_ankle_x" type="continuous">
		<parent link="link1_13" />
		<child link="link1_14" />
		<dynamics damping="1.0" friction="0.0001" />
		<origin rpy="0.00000 0.00000 0.00000" xyz="0.00000 0.00000 -0.02000" />
		<axis xyz="1.00000 0.00000 0.00000" />
	</joint>
	<joint name="jointfix_0_14" type="fixed">
		<parent link="link1_14" />
		<child link="right_foot" />
		<dynamics damping="1.0" friction="0.0001" />
		<origin rpy="0.00000 -0.00000 0.00000" xyz="0.00000 0.00000 -0.04000" />
		<axis xyz="0.00000 0.00000 0.00000" />
	</joint>
	<joint name="left_hip_x" type="continuous">
		<parent link="pelvis" />
		<child link="link1_16" />
		<dynamics damping="1.0" friction="0.0001" />
		<origin rpy="0.00000 -0.00000 0.00000" xyz="0.00000 0.05000 -0.02000" />
		<axis xyz="-1.00000 0.00000 0.00000" />
	</joint>
	<joint name="left_hip_z" type="continuous">
		<parent link="link1_16" />
		<child link="link1_17" />
		<dynamics damping="1.0" friction="0.0001" />
		<origin rpy="0.00000 -0.00000 0.00000" xyz="0.00000 0.00000 0.00000" />
		<axis xyz="0.00000 0.00000 -1.00000" />
	</joint>
	<joint name="left_hip_y" type="continuous">
		<parent link="link1_17" />
		<child link="link1_18" />
		<dynamics damping="1.0" friction="0.0001" />
		<origin rpy="0.00000 -0.00000 0.00000" xyz="0.00000 0.00000 0.00000" />
		<axis xyz="0.00000 1.00000 0.00000" />
	</joint>
	<joint name="jointfix_5_18" type="fixed">
		<parent link="link1_18" />
		<child link="left_thigh" />
		<dynamics damping="1.0" friction="0.0001" />
		<origin rpy="0.00000 -0.00000 0.00000" xyz="0.00000 0.00000 0.00000" />
		<axis xyz="0.00000 0.00000 0.00000" />
	</joint>
	<joint name="left_knee" type="continuous">
		<parent link="left_thigh" />
		<child link="link1_20" />
		<dynamics damping="1.0" friction="0.0001" />
		<origin rpy="0.00000 0.00000 0.00000" xyz="0.00000 0.00000 -0.19150" />
		<axis xyz="0.00000 -1.00000 0.00000" />
	</joint>
	<joint name="jointfix_4_20" type="fixed">
		<parent link="link1_20" />
		<child link="left_shin" />
		<dynamics damping="1.0" friction="0.0001" />
		<origin rpy="0.00000 -0.00000 0.00000" xyz="0.00000 0.00000 -0.01000" />
		<axis xyz="0.00000 0.00000 0.00000" />
	</joint>
	<joint name="left_ankle_y" type="continuous">
		<parent link="left_shin" />
		<child link="link1_22" />
		<dynamics damping="1.0" friction="0.0001" />
		<origin rpy="0.00000 0.00000 0.00000" xyz="0.00000 0.00000 -0.15500" />
		<axis xyz="0.00000 1.00000 0.00000" />
	</joint>
	<joint name="left_ankle_x" type="continuous">
		<parent link="link1_22" />
		<child link="link1_23" />
		<dynamics damping="1.0" friction="0.0001" />
		<origin rpy="0.00000 0.00000 0.00000" xyz="0.00000 0.00000 -0.02000" />
		<axis xyz="1.00000 0.00000 0.00000" />
	</joint>
	<joint name="jointfix_3_23" type="fixed">
		<parent link="link1_23" />
		<child link="left_foot" />
		<dynamics damping="1.0" friction="0.0001" />
		<origin rpy="0.00000 -0.00000 0.00000" xyz="0.00000 0.00000 -0.04000" />
		<axis xyz="0.00000 0.00000 0.00000" />
	</joint>
	<joint name="right_shoulder1" type="continuous">
		<parent link="torso" />
		<child link="link1_25" />
		<dynamics damping="1.0" friction="0.0001" />
		<origin rpy="0.00000 -0.00000 0.00000" xyz="0.00000 -0.08500 0.03000" />
		<axis xyz="2.00000 1.00000 1.00000" />
	</joint>
	<joint name="right_shoulder2" type="continuous">
		<parent link="link1_25" />
		<child link="link1_26" />
		<dynamics damping="1.0" friction="0.0001" />
		<origin rpy="0.00000 -0.00000 0.00000" xyz="0.00000 0.00000 0.00000" />
		<axis xyz="0.00000 -1.00000 1.00000" />
	</joint>
	<joint name="jointfix_9_26" type="fixed">
		<parent link="link1_26" />
		<child link="right_upper_arm" />
		<dynamics damping="1.0" friction="0.0001" />
		<origin rpy="0.00000 -0.00000 0.00000" xyz="0.00000 0.00000 0.00000" />
		<axis xyz="0.00000 0.00000 0.00000" />
	</joint>
	<joint name="right_elbow" type="continuous">
		<parent link="right_upper_arm" />
		<child link="link1_28" />
		<dynamics damping="1.0" friction="0.0001" />
		<origin rpy="0.00000 -0.00000 0.00000" xyz="0.09000 -0.09000 -0.09000" />
		<axis xyz="0.00000 -1.00000 1.00000" />
	</joint>
	<joint name="jointfix_8_28" type="fixed">
		<parent link="link1_28" />
		<child link="right_lower_arm" />
		<dynamics damping="1.0" friction="0.0001" />
		<origin rpy="0.00000 -0.00000 0.00000" xyz="0.00000 0.00000 0.00000" />
		<axis xyz="0.00000 0.00000 0.00000" />
	</joint>
	<joint name="left_shoulder1" type="continuous">
		<parent link="torso" />
		<child link="link1_30" />
		<dynamics damping="1.0" friction="0.0001" />
		<origin rpy="0.00000 -0.00000 0.00000" xyz="0.00000 0.08500 0.03000" />
		<axis xyz="2.00000 -1.00000 1.00000" />
	</joint>
	<joint name="left_shoulder2" type="continuous">
		<parent link="link1_30" />
		<child link="link1_31" />
		<dynamics damping="1.0" friction="0.0001" />
		<origin rpy="0.00000 -0.00000 0.00000" xyz="0.00000 0.00000 0.00000" />
		<axis xyz="0.00000 1.00000 1.00000" />
	</joint>
	<joint name="jointfix_11_31" type="fixed">
		<parent link="link1_31" />
		<child link="left_upper_arm" />
		<dynamics damping="1.0" friction="0.0001" />
		<origin rpy="0.00000 -0.00000 0.00000" xyz="0.00000 0.00000 0.00000" />
		<axis xyz="0.00000 0.00000 0.00000" />
	</joint>
	<joint name="left_elbow" type="continuous">
		<parent link="left_upper_arm" />
		<child link="link1_33" />
		<dynamics damping="1.0" friction="0.0001" />
		<origin rpy="0.00000 -0.00000 0.00000" xyz="0.09000 0.09000 -0.09000" />
		<axis xyz="0.00000 -1.00000 -1.00000" />
	</joint>
	<joint name="jointfix_10_33" type="fixed">
		<parent link="link1_33" />
		<child link="left_lower_arm" />
		<dynamics damping="1.0" friction="0.0001" />
		<origin rpy="0.00000 -0.00000 0.00000" xyz="0.00000 0.00000 0.00000" />
		<axis xyz="0.00000 0.00000 0.00000" />
	</joint>
</robot>